Workbook

Sheet Master
A1: Capability | B1: Feature | C1: Application | D1: Requested By | E1: Phase | F1: Start Date | G1: End Date
B2: Cruise Reports | C2: Cruise | D2: FO | E2: Now | F2: =_xlfn.XLOOKUP(E2, Phase!A$2:A$4, Phase!B$2:B$4,"") -> 45847 | G2: =_xlfn.XLOOKUP(E2, Phase!A$2:A$4, Phase!C$2:C$4,"") -> 45930
A3: Roster | B3: Flight Crew Recency | C3: Crew Pulse | D3: FO | E3: Now | F3: =_xlfn.XLOOKUP(E3, Phase!A$2:A$4, Phase!B$2:B$4,"") -> 45847 | G3: =_xlfn.XLOOKUP(E3, Phase!A$2:A$4, Phase!C$2:C$4,"") -> 45930
B4: Printing of GCAA licences in HQ | C4: Cruise | D4: FO | E4: Now | F4: =_xlfn.XLOOKUP(E4, Phase!A$2:A$4, Phase!B$2:B$4,"") -> 45847 | G4: =_xlfn.XLOOKUP(E4, Phase!A$2:A$4, Phase!C$2:C$4,"") -> 45930
B5: Crew Pulse IMprovements | C5: Cruise | D5: FO | E5: Now | F5: =_xlfn.XLOOKUP(E5, Phase!A$2:A$4, Phase!B$2:B$4,"") -> 45847 | G5: =_xlfn.XLOOKUP(E5, Phase!A$2:A$4, Phase!C$2:C$4,"") -> 45930
B6: Crew Pulse - eTechLog onboarded features | C6: Crew Pulse | D6: FO | E6: Now | F6: =_xlfn.XLOOKUP(E6, Phase!A$2:A$4, Phase!B$2:B$4,"") -> 45847 | G6: =_xlfn.XLOOKUP(E6, Phase!A$2:A$4, Phase!C$2:C$4,"") -> 45930
B7: Duty overlap report | C7: Cruise | D7: FO | E7: Now | F7: =_xlfn.XLOOKUP(E7, Phase!A$2:A$4, Phase!B$2:B$4,"") -> 45847 | G7: =_xlfn.XLOOKUP(E7, Phase!A$2:A$4, Phase!C$2:C$4,"") -> 45930
A8: Crew Comms. & Engagement | B8: Notifiations to Crew based on the A/C registration number. | C8: Crew Pulse | D8: FO | E8: Later | F8: =_xlfn.XLOOKUP(E8, Phase!A$2:A$4, Phase!B$2:B$4,"") -> 46029 | G8: =_xlfn.XLOOKUP(E8, Phase!A$2:A$4, Phase!C$2:C$4,"") -> 46142
B9: FCL- ELP qualification not be updated with TA validity for Typerating/fleet transfer | C9: Cruise | D9: FO | E9: Now | F9: =_xlfn.XLOOKUP(E9, Phase!A$2:A$4, Phase!B$2:B$4,"") -> 45847 | G9: =_xlfn.XLOOKUP(E9, Phase!A$2:A$4, Phase!C$2:C$4,"") -> 45930
A10: Performance & HR | B10: Crew Pulse - submission of EL, PTLB and Parental leave | C10: Crew Pulse | D10: FO | E10: Later | F10: =_xlfn.XLOOKUP(E10, Phase!A$2:A$4, Phase!B$2:B$4,"") -> 46029 | G10: =_xlfn.XLOOKUP(E10, Phase!A$2:A$4, Phase!C$2:C$4,"") -> 46142
A11: Roster | B11: FCL - Variation flights for CC to also show on Captain roster and marked appropriately | C11: Crew Pulse | D11: FO | E11: Now | F11: =_xlfn.XLOOKUP(E11, Phase!A$2:A$4, Phase!B$2:B$4,"") -> 45847 | G11: =_xlfn.XLOOKUP(E11, Phase!A$2:A$4, Phase!C$2:C$4,"") -> 45930
B12: Cruise - Crew List Data Element | C12: Cruise | D12: FO | E12: Next | F12: =_xlfn.XLOOKUP(E12, Phase!A$2:A$4, Phase!B$2:B$4,"") -> 45931 | G12: =_xlfn.XLOOKUP(E12, Phase!A$2:A$4, Phase!C$2:C$4,"") -> 45663
B13: My Crew Function | C13: Cruise | D13: FO | E13: Now | F13: =_xlfn.XLOOKUP(E13, Phase!A$2:A$4, Phase!B$2:B$4,"") -> 45847 | G13: =_xlfn.XLOOKUP(E13, Phase!A$2:A$4, Phase!C$2:C$4,"") -> 45930
A14: Crew Comms. & Engagement | B14: Chatbot to manage Crew calls during disruption based on criticality Notification improvements | C14: Crew Pulse | D14: FO | E14: Later | F14: =_xlfn.XLOOKUP(E14, Phase!A$2:A$4, Phase!B$2:B$4,"") -> 46029 | G14: =_xlfn.XLOOKUP(E14, Phase!A$2:A$4, Phase!C$2:C$4,"") -> 46142
B15: UAE national new joiner pilots not to receive Foreign conversion alert when PPCINI is added in IOB. | C15: Cruise | D15: FO | E15: Later | F15: =_xlfn.XLOOKUP(E15, Phase!A$2:A$4, Phase!B$2:B$4,"") -> 46029 | G15: =_xlfn.XLOOKUP(E15, Phase!A$2:A$4, Phase!C$2:C$4,"") -> 46142
B16: Pre-EK airline | C16: Cruise | D16: FO | E16: Next | F16: =_xlfn.XLOOKUP(E16, Phase!A$2:A$4, Phase!B$2:B$4,"") -> 45931 | G16: =_xlfn.XLOOKUP(E16, Phase!A$2:A$4, Phase!C$2:C$4,"") -> 45663
A17: Duty Preparation | B17: Crew Pulse Check-in Requirement - Discussion on New Features | C17: Crew Pulse | D17: FO | E17: Later | F17: =_xlfn.XLOOKUP(E17, Phase!A$2:A$4, Phase!B$2:B$4,"") -> 46029 | G17: =_xlfn.XLOOKUP(E17, Phase!A$2:A$4, Phase!C$2:C$4,"") -> 46142
B18: GCAA Service - Approved Date | C18: Cruise | D18: FO | E18: Now | F18: =_xlfn.XLOOKUP(E18, Phase!A$2:A$4, Phase!B$2:B$4,"") -> 45847 | G18: =_xlfn.XLOOKUP(E18, Phase!A$2:A$4, Phase!C$2:C$4,"") -> 45930
B19: FCL - Automation of TMS codes update | C19: Cruise | D19: FO | E19: Next | F19: =_xlfn.XLOOKUP(E19, Phase!A$2:A$4, Phase!B$2:B$4,"") -> 45931 | G19: =_xlfn.XLOOKUP(E19, Phase!A$2:A$4, Phase!C$2:C$4,"") -> 45663
A20: Duty Preparation | B20: Crew ops/ Fleet Crew Pulse - My Flight Docs | C20: Crew Pulse | D20: FO | E20: Now | F20: =_xlfn.XLOOKUP(E20, Phase!A$2:A$4, Phase!B$2:B$4,"") -> 45847 | G20: =_xlfn.XLOOKUP(E20, Phase!A$2:A$4, Phase!C$2:C$4,"") -> 45930
A21: Crew Comms. & Engagement | B21: Broadcast Reels | C21: Crew Pulse | D21: SD | E21: Now | F21: =_xlfn.XLOOKUP(E21, Phase!A$2:A$4, Phase!B$2:B$4,"") -> 45847 | G21: =_xlfn.XLOOKUP(E21, Phase!A$2:A$4, Phase!C$2:C$4,"") -> 45930
A22: Crew Comms. & Engagement | B22: Push notification to select crew and flights (Crew Hotel Survey) | C22: Crew Pulse | D22: SD | E22: Now | F22: =_xlfn.XLOOKUP(E22, Phase!A$2:A$4, Phase!B$2:B$4,"") -> 45847 | G22: =_xlfn.XLOOKUP(E22, Phase!A$2:A$4, Phase!C$2:C$4,"") -> 45930
A23: Roster | B23: eSwap | C23: Crew Pulse | D23: SD | E23: Now | F23: =_xlfn.XLOOKUP(E23, Phase!A$2:A$4, Phase!B$2:B$4,"") -> 45847 | G23: =_xlfn.XLOOKUP(E23, Phase!A$2:A$4, Phase!C$2:C$4,"") -> 45930
B24: Employee from EK Grade moved to Cabin Crew Grade | C24: Paradise | D24: SD | E24: Now | F24: =_xlfn.XLOOKUP(E24, Phase!A$2:A$4, Phase!B$2:B$4,"") -> 45847 | G24: =_xlfn.XLOOKUP(E24, Phase!A$2:A$4, Phase!C$2:C$4,"") -> 45930
B25: Coruson flow to Paradise and SAFE historical data | C25: Paradise | D25: SD | E25: Now | F25: =_xlfn.XLOOKUP(E25, Phase!A$2:A$4, Phase!B$2:B$4,"") -> 45847 | G25: =_xlfn.XLOOKUP(E25, Phase!A$2:A$4, Phase!C$2:C$4,"") -> 45930
A26: Duty Preparation | B26: My Flight Documents - GCAA Attestation - Phase 2 | C26: Crew Pulse | D26: SD | E26: Now | F26: =_xlfn.XLOOKUP(E26, Phase!A$2:A$4, Phase!B$2:B$4,"") -> 45847 | G26: =_xlfn.XLOOKUP(E26, Phase!A$2:A$4, Phase!C$2:C$4,"") -> 45930
A27: Crew Comms. & Engagement | B27: Push notifications to stakeholders when there are comments posted under respective articles | C27: Crew Pulse | D27: SD | E27: Now | F27: =_xlfn.XLOOKUP(E27, Phase!A$2:A$4, Phase!B$2:B$4,"") -> 45847 | G27: =_xlfn.XLOOKUP(E27, Phase!A$2:A$4, Phase!C$2:C$4,"") -> 45930
B28: Coruson | C28: Paradise | D28: SD | E28: Now | F28: =_xlfn.XLOOKUP(E28, Phase!A$2:A$4, Phase!B$2:B$4,"") -> 45847 | G28: =_xlfn.XLOOKUP(E28, Phase!A$2:A$4, Phase!C$2:C$4,"") -> 45930
A29: Duty Preparation | B29: Showing XXO (Day off) on Roster | C29: Crew Pulse | D29: SD | E29: Now | F29: =_xlfn.XLOOKUP(E29, Phase!A$2:A$4, Phase!B$2:B$4,"") -> 45847 | G29: =_xlfn.XLOOKUP(E29, Phase!A$2:A$4, Phase!C$2:C$4,"") -> 45930
A30: Roster | B30: Disruption Mode - Roster Changes and Flight Changes | C30: Crew Pulse | D30: SD | E30: Now | F30: =_xlfn.XLOOKUP(E30, Phase!A$2:A$4, Phase!B$2:B$4,"") -> 45847 | G30: =_xlfn.XLOOKUP(E30, Phase!A$2:A$4, Phase!C$2:C$4,"") -> 45930
A31: Crew Comms. & Engagement | B31: Real-time Crew Interaction Monitoring of articles | C31: Crew Pulse | D31: SD | E31: Now | F31: =_xlfn.XLOOKUP(E31, Phase!A$2:A$4, Phase!B$2:B$4,"") -> 45847 | G31: =_xlfn.XLOOKUP(E31, Phase!A$2:A$4, Phase!C$2:C$4,"") -> 45930
A32: Crew Comms. & Engagement | B32: Like and Love feature of the comments and article | C32: Crew Pulse | D32: SD | E32: Now | F32: =_xlfn.XLOOKUP(E32, Phase!A$2:A$4, Phase!B$2:B$4,"") -> 45847 | G32: =_xlfn.XLOOKUP(E32, Phase!A$2:A$4, Phase!C$2:C$4,"") -> 45930
B33: CMC Auto Qualification Update for Cabin Crew | C33: Paradise | D33: SD | E33: Now | F33: =_xlfn.XLOOKUP(E33, Phase!A$2:A$4, Phase!B$2:B$4,"") -> 45847 | G33: =_xlfn.XLOOKUP(E33, Phase!A$2:A$4, Phase!C$2:C$4,"") -> 45930
A34: Pre-Flight (Day of Ops) | B34: E-attestation to MFD on Crew Pulse | C34: Crew Pulse | D34: SD | E34: Now | F34: =_xlfn.XLOOKUP(E34, Phase!A$2:A$4, Phase!B$2:B$4,"") -> 45847 | G34: =_xlfn.XLOOKUP(E34, Phase!A$2:A$4, Phase!C$2:C$4,"") -> 45930
A35: Pre-Flight (Day of Ops) | B35: CMC Digital to MFD on Crew Pulse | C35: Crew Pulse | D35: SD | E35: Now | F35: =_xlfn.XLOOKUP(E35, Phase!A$2:A$4, Phase!B$2:B$4,"") -> 45847 | G35: =_xlfn.XLOOKUP(E35, Phase!A$2:A$4, Phase!C$2:C$4,"") -> 45930
B36: Personal Travel and Duty Overlap Enhancement | C36: Paradise | D36: SD | E36: Now | F36: =_xlfn.XLOOKUP(E36, Phase!A$2:A$4, Phase!B$2:B$4,"") -> 45847 | G36: =_xlfn.XLOOKUP(E36, Phase!A$2:A$4, Phase!C$2:C$4,"") -> 45930
B37: Coruson Go Live with CAR Reports | C37: Paradise | D37: SD | E37: Now | F37: =_xlfn.XLOOKUP(E37, Phase!A$2:A$4, Phase!B$2:B$4,"") -> 45847 | G37: =_xlfn.XLOOKUP(E37, Phase!A$2:A$4, Phase!C$2:C$4,"") -> 45930
B38: Auto Calculation of Attendance Matrix | C38: Paradise | D38: SD | E38: Now | F38: =_xlfn.XLOOKUP(E38, Phase!A$2:A$4, Phase!B$2:B$4,"") -> 45847 | G38: =_xlfn.XLOOKUP(E38, Phase!A$2:A$4, Phase!C$2:C$4,"") -> 45930
A39: Crew Comms. & Engagement | B39: Text to Speech | C39: Crew Pulse | D39: SD | E39: Now | F39: =_xlfn.XLOOKUP(E39, Phase!A$2:A$4, Phase!B$2:B$4,"") -> 45847 | G39: =_xlfn.XLOOKUP(E39, Phase!A$2:A$4, Phase!C$2:C$4,"") -> 45930
A40: Roster | B40: Flights requiring acclimatization | C40: Crew Pulse | D40: SD | E40: Now | F40: =_xlfn.XLOOKUP(E40, Phase!A$2:A$4, Phase!B$2:B$4,"") -> 45847 | G40: =_xlfn.XLOOKUP(E40, Phase!A$2:A$4, Phase!C$2:C$4,"") -> 45930
...

Sheet Now
A1: Capability | B1: Feature | C1: Application | D1: Requested By | E1: Start Date | F1: End Date
A2: {=_xlfn.LET(_xlpm.data,_xlfn._xlws.FILTER(_xlfn.CHOOSECOLS(Master!A2:G94,1,2,3,4,6,7), Master!E2:E94="Now",""), IF(_xlpm.data=0, "", _xlpm.data))} | B2: Cruise Reports | C2: Cruise | D2: FO | E2: 45847 | F2: 45930
A3: Roster | B3: Flight Crew Recency | C3: Crew Pulse | D3: FO | E3: 45847 | F3: 45930
B4: Printing of GCAA licences in HQ | C4: Cruise | D4: FO | E4: 45847 | F4: 45930
B5: Crew Pulse IMprovements | C5: Cruise | D5: FO | E5: 45847 | F5: 45930
B6: Crew Pulse - eTechLog onboarded features | C6: Crew Pulse | D6: FO | E6: 45847 | F6: 45930
B7: Duty overlap report | C7: Cruise | D7: FO | E7: 45847 | F7: 45930
B8: FCL- ELP qualification not be updated with TA validity for Typerating/fleet transfer | C8: Cruise | D8: FO | E8: 45847 | F8: 45930
A9: Roster | B9: FCL - Variation flights for CC to also show on Captain roster and marked appropriately | C9: Crew Pulse | D9: FO | E9: 45847 | F9: 45930
B10: My Crew Function | C10: Cruise | D10: FO | E10: 45847 | F10: 45930
B11: GCAA Service - Approved Date | C11: Cruise | D11: FO | E11: 45847 | F11: 45930
A12: Duty Preparation | B12: Crew ops/ Fleet Crew Pulse - My Flight Docs | C12: Crew Pulse | D12: FO | E12: 45847 | F12: 45930
A13: Crew Comms. & Engagement | B13: Broadcast Reels | C13: Crew Pulse | D13: SD | E13: 45847 | F13: 45930
A14: Crew Comms. & Engagement | B14: Push notification to select crew and flights (Crew Hotel Survey) | C14: Crew Pulse | D14: SD | E14: 45847 | F14: 45930
A15: Roster | B15: eSwap | C15: Crew Pulse | D15: SD | E15: 45847 | F15: 45930
B16: Employee from EK Grade moved to Cabin Crew Grade | C16: Paradise | D16: SD | E16: 45847 | F16: 45930
B17: Coruson flow to Paradise and SAFE historical data | C17: Paradise | D17: SD | E17: 45847 | F17: 45930
A18: Duty Preparation | B18: My Flight Documents - GCAA Attestation - Phase 2 | C18: Crew Pulse | D18: SD | E18: 45847 | F18: 45930
A19: Crew Comms. & Engagement | B19: Push notifications to stakeholders when there are comments posted under respective articles | C19: Crew Pulse | D19: SD | E19: 45847 | F19: 45930
B20: Coruson | C20: Paradise | D20: SD | E20: 45847 | F20: 45930
A21: Duty Preparation | B21: Showing XXO (Day off) on Roster | C21: Crew Pulse | D21: SD | E21: 45847 | F21: 45930
A22: Roster | B22: Disruption Mode - Roster Changes and Flight Changes | C22: Crew Pulse | D22: SD | E22: 45847 | F22: 45930
A23: Crew Comms. & Engagement | B23: Real-time Crew Interaction Monitoring of articles | C23: Crew Pulse | D23: SD | E23: 45847 | F23: 45930
A24: Crew Comms. & Engagement | B24: Like and Love feature of the comments and article | C24: Crew Pulse | D24: SD | E24: 45847 | F24: 45930
B25: CMC Auto Qualification Update for Cabin Crew | C25: Paradise | D25: SD | E25: 45847 | F25: 45930
A26: Pre-Flight (Day of Ops) | B26: E-attestation to MFD on Crew Pulse | C26: Crew Pulse | D26: SD | E26: 45847 | F26: 45930
A27: Pre-Flight (Day of Ops) | B27: CMC Digital to MFD on Crew Pulse | C27: Crew Pulse | D27: SD | E27: 45847 | F27: 45930
B28: Personal Travel and Duty Overlap Enhancement | C28: Paradise | D28: SD | E28: 45847 | F28: 45930
B29: Coruson Go Live with CAR Reports | C29: Paradise | D29: SD | E29: 45847 | F29: 45930
B30: Auto Calculation of Attendance Matrix | C30: Paradise | D30: SD | E30: 45847 | F30: 45930
A31: Crew Comms. & Engagement | B31: Text to Speech | C31: Crew Pulse | D31: SD | E31: 45847 | F31: 45930
A32: Roster | B32: Flights requiring acclimatization | C32: Crew Pulse | D32: SD | E32: 45847 | F32: 45930
B33: Multiple Sub Incidents in One Incident | C33: Paradise | D33: SD | E33: 45847 | F33: 45930
A34: Duty Preparation | B34: Flight Details 2.0: Wake-up/Pick up time | C34: Crew Pulse | D34: SD | E34: 45847 | F34: 45930

Sheet Next
A1: Capability | B1: Feature | C1: Application | D1: Requested By | E1: Start Date | F1: End Date
A2: {=_xlfn.LET(_xlpm.data,_xlfn._xlws.FILTER(_xlfn.CHOOSECOLS(Master!A2:G94,1,2,3,4,6,7),Master!E2:E94="Next",""),IF(_xlpm.data=0,"",_xlpm.data))} | B2: Cruise - Crew List Data Element | C2: Cruise | D2: FO | E2: 45931 | F2: 45663
B3: Pre-EK airline | C3: Cruise | D3: FO | E3: 45931 | F3: 45663
B4: FCL - Automation of TMS codes update | C4: Cruise | D4: FO | E4: 45931 | F4: 45663
A5: Crew Comms. & Engagement | B5: Podcasts | C5: Crew Pulse | D5: SD | E5: 45931 | F5: 45663
A6: Crew Comms. & Engagement | B6: New Engagement Calendar | C6: Crew Pulse | D6: SD | E6: 45931 | F6: 45663
A7: Crew Comms. & Engagement | B7: Engagement Countdown Feature | C7: Crew Pulse | D7: SD | E7: 45931 | F7: 45663
B8: Crew Pulse restricted access | C8: Crew Pulse | D8: SD | E8: 45931 | F8: 45663
A9: Safety & Emergency | B9: Locate Crew | C9: Crew Pulse | D9: SD | E9: 45931 | F9: 45663
A10: Duty Preparation | B10: Flight Details 2.0: Crew Hotel | C10: Crew Pulse | D10: SD | E10: 45931 | F10: 45663

Sheet Later
A1: Feature | B1: Application | C1: Requested By | D1: Phase | E1: Start Date | F1: End Date
A2: {=_xlfn.LET(_xlpm.data,_xlfn._xlws.FILTER(_xlfn.CHOOSECOLS(Master!A2:G94,1,2,3,4,6,7),Master!E2:E94="Later",""),IF(_xlpm.data=0,"",_xlpm.data))} -> Crew Comms. & Engagement | B2: Notifiations to Crew based on the A/C registration number. | C2: Crew Pulse | D2: FO | E2: 46029 | F2: 46142
A3: Performance & HR | B3: Crew Pulse - submission of EL, PTLB and Parental leave | C3: Crew Pulse | D3: FO | E3: 46029 | F3: 46142
A4: Crew Comms. & Engagement | B4: Chatbot to manage Crew calls during disruption based on criticality Notification improvements | C4: Crew Pulse | D4: FO | E4: 46029 | F4: 46142
B5: UAE national new joiner pilots not to receive Foreign conversion alert when PPCINI is added in IOB. | C5: Cruise | D5: FO | E5: 46029 | F5: 46142
A6: Duty Preparation | B6: Crew Pulse Check-in Requirement - Discussion on New Features | C6: Crew Pulse | D6: FO | E6: 46029 | F6: 46142
A7: Duty Preparation | B7: Crew Bus Tracking (Cabin Crew Landside Transport) | C7: Crew Pulse | D7: SD | E7: 46029 | F7: 46142
A8: Crew Comms. & Engagement | B8: Chatbot & Live Chat | C8: Crew Pulse | D8: SD | E8: 46029 | F8: 46142
A9: Crew Comms. & Engagement | B9: Crew Connect Token Request | C9: Crew Pulse | D9: SD | E9: 46029 | F9: 46142
A10: Crew Comms. & Engagement | B10: Crew Pulse module for Crew Connect Services | C10: Crew Pulse | D10: SD | E10: 46029 | F10: 46142
B11: Chatbot to have automation on alerts for concern Alerts | C11: Paradise | D11: SD | E11: 46029 | F11: 46142
A12: Performance & HR | B12: Crew to Report SK via Crew Pulse | C12: Crew Pulse | D12: SD | E12: 46029 | F12: 46142
A13: Duty Preparation | B13: Access to SOPs | C13: Crew Pulse | D13: SD | E13: 46029 | F13: 46142
A14: Post-Flight | B14: Destination Pages - Contextualised Content to Cabin Crew | C14: Crew Pulse | D14: SD | E14: 46029 | F14: 46142
A15: Duty Preparation | B15: Flight Details 2.0: Crew Rest | C15: Crew Pulse | D15: SD | E15: 46029 | F15: 46142
A16: Duty Preparation | B16: Flight Details 2.0: Service Details Enhancements | C16: Crew Pulse | D16: SD | E16: 46029 | F16: 46142
A17: Safety & Emergency | B17: Safe Talk | C17: Crew Pulse | D17: SD | E17: 46029 | F17: 46142
A18: Duty Preparation | B18: Aircraft Details 2.0 | C18: Crew Pulse | D18: SD | E18: 46029 | F18: 46142
A19: Crew Comms. & Engagement | B19: Widgets | C19: Crew Pulse | D19: SD | E19: 46029 | F19: 46142
A20: Crew Comms. & Engagement | B20: Microlearning | C20: Crew Pulse | D20: SD | E20: 46029 | F20: 46142
A21: Duty Preparation | B21: Crew Meal Pre-Order | C21: Crew Pulse | D21: SD | E21: 46029 | F21: 46142

Sheet Capabilities
A1: Capability | B1: Application
A2: Roster | B2: Crew Pulse
A3: Duty Preparation | B3: Crew Pulse
A4: Pre-Flight (Day of Ops) | B4: Crew Pulse
A5: Post-Flight | B5: Crew Pulse
A6: Crew Comms. & Engagement | B6: Crew Pulse
A7: Safety & Emergency | B7: Crew Pulse
A8: Performance & HR | B8: Crew Pulse

Sheet Phase
A1: Phase | B1: Phase | C1: Phase
A2: Now | B2: 45847 | C2: 45930
A3: Next | B3: 45931 | C3: 45663
A4: Later | B4: 46029 | C4: 46142
